<?xml version="1.0" encoding="UTF-8"?>
<testng-results ignored="0" total="2" passed="0" failed="2" skipped="0">
  <reporter-output>
  </reporter-output>
  <suite started-at="2022-04-07T14:09:42Z" name="Default suite" finished-at="2022-04-07T14:10:03Z" duration-ms="21115">
    <groups>
    </groups>
    <test started-at="2022-04-07T14:09:42Z" name="Default test" finished-at="2022-04-07T14:10:03Z" duration-ms="21115">
      <class name="demoOpenCartTest.TestClass">
        <test-method is-config="true" signature="f()[pri:0, instance:demoOpenCartTest.TestClass@609e8838]" started-at="2022-04-07T14:09:42Z" name="f" finished-at="2022-04-07T14:09:51Z" duration-ms="9636" status="PASS">
          <reporter-output>
          </reporter-output>
        </test-method> <!-- f -->
        <test-method signature="test1()[pri:0, instance:demoOpenCartTest.TestClass@609e8838]" started-at="2022-04-07T14:09:51Z" name="test1" finished-at="2022-04-07T14:09:51Z" duration-ms="22" status="FAIL">
          <exception class="java.lang.AssertionError">
            <message>
              <![CDATA[expected null, but was:<ChromeDriver: chrome on WINDOWS (41ffc18ee6918db3c461ff385eccdf09)>]]>
            </message>
            <full-stacktrace>
              <![CDATA[java.lang.AssertionError: expected null, but was:<ChromeDriver: chrome on WINDOWS (41ffc18ee6918db3c461ff385eccdf09)>
at org.junit.Assert.fail(Assert.java:88)
at org.junit.Assert.failNotNull(Assert.java:664)
at org.junit.Assert.assertNull(Assert.java:646)
at org.junit.Assert.assertNull(Assert.java:656)
at demoOpenCartTest.TestClass.test1(TestClass.java:24)
at java.base/jdk.internal.reflect.NativeMethodAccessorImpl.invoke0(Native Method)
at java.base/jdk.internal.reflect.NativeMethodAccessorImpl.invoke(NativeMethodAccessorImpl.java:77)
at java.base/jdk.internal.reflect.DelegatingMethodAccessorImpl.invoke(DelegatingMethodAccessorImpl.java:43)
at java.base/java.lang.reflect.Method.invoke(Method.java:568)
at org.testng.internal.MethodInvocationHelper.invokeMethod(MethodInvocationHelper.java:124)
at org.testng.internal.Invoker.invokeMethod(Invoker.java:583)
at org.testng.internal.Invoker.invokeTestMethod(Invoker.java:719)
at org.testng.internal.Invoker.invokeTestMethods(Invoker.java:989)
at org.testng.internal.TestMethodWorker.invokeTestMethods(TestMethodWorker.java:125)
at org.testng.internal.TestMethodWorker.run(TestMethodWorker.java:109)
at org.testng.TestRunner.privateRun(TestRunner.java:648)
at org.testng.TestRunner.run(TestRunner.java:505)
at org.testng.SuiteRunner.runTest(SuiteRunner.java:455)
at org.testng.SuiteRunner.runSequentially(SuiteRunner.java:450)
at org.testng.SuiteRunner.privateRun(SuiteRunner.java:415)
at org.testng.SuiteRunner.run(SuiteRunner.java:364)
at org.testng.SuiteRunnerWorker.runSuite(SuiteRunnerWorker.java:52)
at org.testng.SuiteRunnerWorker.run(SuiteRunnerWorker.java:84)
at org.testng.TestNG.runSuitesSequentially(TestNG.java:1208)
at org.testng.TestNG.runSuitesLocally(TestNG.java:1137)
at org.testng.TestNG.runSuites(TestNG.java:1049)
at org.testng.TestNG.run(TestNG.java:1017)
at org.testng.remote.AbstractRemoteTestNG.run(AbstractRemoteTestNG.java:115)
at org.testng.remote.RemoteTestNG.initAndRun(RemoteTestNG.java:251)
at org.testng.remote.RemoteTestNG.main(RemoteTestNG.java:77)
]]>
            </full-stacktrace>
          </exception> <!-- java.lang.AssertionError -->
          <reporter-output>
          </reporter-output>
        </test-method> <!-- test1 -->
        <test-method is-config="true" signature="close()[pri:0, instance:demoOpenCartTest.TestClass@609e8838]" started-at="2022-04-07T14:09:52Z" name="close" finished-at="2022-04-07T14:09:52Z" duration-ms="579" status="PASS">
          <reporter-output>
          </reporter-output>
        </test-method> <!-- close -->
        <test-method is-config="true" signature="f()[pri:0, instance:demoOpenCartTest.TestClass@609e8838]" started-at="2022-04-07T14:09:52Z" name="f" finished-at="2022-04-07T14:10:02Z" duration-ms="9378" status="PASS">
          <reporter-output>
          </reporter-output>
        </test-method> <!-- f -->
        <test-method signature="test2()[pri:0, instance:demoOpenCartTest.TestClass@609e8838]" started-at="2022-04-07T14:10:02Z" name="test2" finished-at="2022-04-07T14:10:02Z" duration-ms="3" status="FAIL">
          <exception class="java.lang.AssertionError">
            <full-stacktrace>
              <![CDATA[java.lang.AssertionError
at org.junit.Assert.fail(Assert.java:86)
at org.junit.Assert.assertTrue(Assert.java:41)
at org.junit.Assert.assertFalse(Assert.java:64)
at org.junit.Assert.assertFalse(Assert.java:74)
at demoOpenCartTest.TestClass.test2(TestClass.java:28)
at java.base/jdk.internal.reflect.NativeMethodAccessorImpl.invoke0(Native Method)
at java.base/jdk.internal.reflect.NativeMethodAccessorImpl.invoke(NativeMethodAccessorImpl.java:77)
at java.base/jdk.internal.reflect.DelegatingMethodAccessorImpl.invoke(DelegatingMethodAccessorImpl.java:43)
at java.base/java.lang.reflect.Method.invoke(Method.java:568)
at org.testng.internal.MethodInvocationHelper.invokeMethod(MethodInvocationHelper.java:124)
at org.testng.internal.Invoker.invokeMethod(Invoker.java:583)
at org.testng.internal.Invoker.invokeTestMethod(Invoker.java:719)
at org.testng.internal.Invoker.invokeTestMethods(Invoker.java:989)
at org.testng.internal.TestMethodWorker.invokeTestMethods(TestMethodWorker.java:125)
at org.testng.internal.TestMethodWorker.run(TestMethodWorker.java:109)
at org.testng.TestRunner.privateRun(TestRunner.java:648)
at org.testng.TestRunner.run(TestRunner.java:505)
at org.testng.SuiteRunner.runTest(SuiteRunner.java:455)
at org.testng.SuiteRunner.runSequentially(SuiteRunner.java:450)
at org.testng.SuiteRunner.privateRun(SuiteRunner.java:415)
at org.testng.SuiteRunner.run(SuiteRunner.java:364)
at org.testng.SuiteRunnerWorker.runSuite(SuiteRunnerWorker.java:52)
at org.testng.SuiteRunnerWorker.run(SuiteRunnerWorker.java:84)
at org.testng.TestNG.runSuitesSequentially(TestNG.java:1208)
at org.testng.TestNG.runSuitesLocally(TestNG.java:1137)
at org.testng.TestNG.runSuites(TestNG.java:1049)
at org.testng.TestNG.run(TestNG.java:1017)
at org.testng.remote.AbstractRemoteTestNG.run(AbstractRemoteTestNG.java:115)
at org.testng.remote.RemoteTestNG.initAndRun(RemoteTestNG.java:251)
at org.testng.remote.RemoteTestNG.main(RemoteTestNG.java:77)
]]>
            </full-stacktrace>
          </exception> <!-- java.lang.AssertionError -->
          <reporter-output>
          </reporter-output>
        </test-method> <!-- test2 -->
        <test-method is-config="true" signature="close()[pri:0, instance:demoOpenCartTest.TestClass@609e8838]" started-at="2022-04-07T14:10:02Z" name="close" finished-at="2022-04-07T14:10:03Z" duration-ms="592" status="PASS">
          <reporter-output>
          </reporter-output>
        </test-method> <!-- close -->
      </class> <!-- demoOpenCartTest.TestClass -->
    </test> <!-- Default test -->
  </suite> <!-- Default suite -->
</testng-results>
